Workbook

Sheet README
B2: Solistice Renewable Energy
B3: Financial Model — README & User Guide
B4: Prepared for internal use | Model currency: USD | Model horizon: FY2026 – FY2030
B6: 1. Purpose & Overview
B8: This workbook is a 5-year (FY2026–FY2030) integrated 3-statement financial model for Solistice, a hypothetical renewable energy startup that develops and operates distributed solar + battery storage systems sold under long-term Power Purchase Agreements (PPAs), alongside a complementary SaaS energy-management product. The model projects project-level revenue, financing (asset debt, ITC direct pay, equity), depreciation, and corporate overhead through to a fully linked Income Statement, Balance Sheet, and Cash Flow Statement, plus a Cap Table for equity ownership across the Seed / SAFE / Series A capital structure.
B10: 2. How to Use This Workbook — Color & Formatting Legend
B12: Blue text | C12: Hardcoded input / assumption — the only cells intended to be edited
B13: Black text | C13: Formula, calculated automatically — do not overwrite
B14: Cell comment (red triangle) | C14: Hover over the cell for a documented methodology note or data source
B16: Every projection year is fully formula-driven from the Assumptions tab — change any blue input cell and the entire model, including the Dashboard and its charts, recalculates automatically. No calculation or output sheet contains a hardcoded number.
B18: 3. Sheet-by-Sheet Guide
B20: Sheet | C20: Purpose | D20: Key Outputs
B21: Assumptions | C21: Every model driver: deployment plan, unit economics, revenue, financing, depreciation & tax, corporate opex, working capital, and book depreciation life. The only sheet meant for direct editing (blue cells). | D21: All downstream drivers
B22: Deploymnet_&_CAPEX_Schedule | C22: Builds the annual system roll-out, gross capex, and sources of funds (debt draw / equity / ITC direct pay) by vintage year. | D22: Capex, ITC cash credit, debt vs. equity funding split
B23: Debt_Schedule | C23: Amortizes each vintage’s asset-level debt draw over its tenor at its contract rate; rolls forward principal balances and interest expense. | D23: Interest expense, ending debt balance
B24: Depreciation_ITC | C24: Straight-line book depreciation for each vintage’s ITC-net basis over its useful life (Assumptions row 56), charged evenly every year the asset is in service — not as a single lump sum. Also tracks the informational tax-basis / IRC §50(c) reduction. | D24: Total book depreciation & amortization (feeds Income Statement)
B25: Revenue_Build | C25: Builds PPA revenue (generation × escalating rate), grid services / demand response revenue, and recurring SaaS revenue (cumulative ARR) by year. | D25: Total revenue by stream
B26: Income_Statement | C26: Consolidates revenue, cost of revenue, opex, EBITDA, D&A, interest, NOL utilization, and the blended-rate tax provision down to net income. | D26: EBITDA, EBIT, Net income, margins
B27: Balance_Sheet | C27: Rolls forward cash, working capital, net PP&E, debt, and equity; ties assets to liabilities + equity every year. | D27: Total assets = Total liabilities + equity (balance check row)
B28: Cash_Flow | C28: Indirect-method cash flow: operating (net income + D&A +/− working capital), investing (capex), and financing (debt draws, equity, Series A proceeds). | D28: Ending cash balance
B29: Cap_Table | C29: Pre- and post-Series A ownership by holder (Founders, SAFE, Seed, ESOP, new investor), including option-pool refresh and dilution mechanics. | D29: Post-Series A ownership %
B30: Dashboard | C30: Live KPI tiles, summary table, and charts built entirely from formulas that pull from the sheets above — nothing here is a pasted value. | D30: Executive summary view
B32: 4. Key Methodology Notes
B34: Depreciation (GAAP vs. tax):
B35: Book depreciation on the Income Statement is straight-line over each vintage’s useful life (default 20 years, blended solar + BESS), charged evenly every year in service. This is intentionally separate from bonus/accelerated tax depreciation, which affects cash taxes but not book D&A — a standard book/tax divergence for capital-intensive businesses.
B36: Blended effective tax rate:
B37: Computed live as Federal + State × (1 − Federal), so the Income Statement tax provision always reflects the current Assumptions tab rates rather than a fixed number.
B38: ITC / Direct Pay:
B39: Modeled as a cash credit received the year the asset is placed in service, reducing net equity capex requirement and the depreciable book basis.
B40: Revenue recognition:
B41: PPA revenue = generation × the vintage’s escalating contract rate; SaaS revenue = cumulative ARR (recurring), not just bookings signed in the year.
B42: Margin assumptions:
B43: O&M, SaaS gross margin, and installed cost per system are calibrated to industry benchmarks for a hybrid solar + storage IPP and an early/growth-stage vertical SaaS product (see Assumptions tab comments for each figure’s basis).
B44: 5. Key Assumptions Snapshot (live — pulls from Assumptions tab)
B46: Driver | C46: Value | D46: Assumptions Cell
B47: Installed cost per system, Year 1 ($) | C47: =Assumptions!D17 -> 1150000 | D47: Assumptions!D15
B48: O&M cost, % of PPA revenue | C48: =Assumptions!D23 -> 0.15 | D48: Assumptions!D21
B49: SaaS gross margin | C49: =Assumptions!D28 -> 0.75 | D49: Assumptions!D26
B50: ITC direct-pay rate | C50: =Assumptions!D35 -> 0.4 | D50: Assumptions!D34
B51: Book depreciation useful life, Year 1 vintage (yrs) | C51: =Assumptions!D57 -> 20 | D51: Assumptions!D56
...

Sheet Dash_Source
B2: KPI Cards
B3: Total Revenue | C3: =SUM(Income_Statement!C9:G9) -> 34727561
B4: EBITDA Margin (%) | C4: =AVERAGE(Income_Statement!C24:G24) -> 0.70073504
B5: Net Margin (%) | C5: =AVERAGE(Income_Statement!C37:G37) -> 0.12468621
B6: Ending Cash Balance | C6: =AVERAGE(Cash_Flow!C26:G26) -> 12767475
B7: Cumulative Sys Deployment | C7: =SUM('Deploymnet_&_CAPEX_Schedule'!C5:G5) -> 65
B9: Revenue Source | C9: =Income_Statement!C4 -> 46023 | D9: =Income_Statement!D4 -> 46388 | E9: =Income_Statement!E4 -> 46753 | F9: =Income_Statement!F4 -> 47119 | G9: =Income_Statement!G4 -> 47484
B10: =Income_Statement!B6 -> PPA revenue | C10: =Income_Statement!C6 -> 1190000 | D10: =Income_Statement!D6 -> 2403651.2 | E10: =Income_Statement!E6 -> 4236423.8 | F10: =Income_Statement!F6 -> 6105622.7 | G10: =Income_Statement!G6 -> 8011972
B11: =Income_Statement!B7 -> Grid services / demand response revenue | C11: =Income_Statement!C7 -> 500000 | D11: =Income_Statement!D7 -> 1012500 | E11: =Income_Statement!E7 -> 1787812.5 | F11: =Income_Statement!F7 -> 2582507.8 | G11: =Income_Statement!G7 -> 3397070.5
B12: =Income_Statement!B8 -> SaaS licensing revenue | C12: =IF(Income_Statement!C8=0,NA(),Income_Statement!C8) -> #N/A | D12: =IF(Income_Statement!D8=0,NA(),Income_Statement!D8) -> 150000 | E12: =IF(Income_Statement!E8=0,NA(),Income_Statement!E8) -> 450000 | F12: =IF(Income_Statement!F8=0,NA(),Income_Statement!F8) -> 1000000 | G12: =IF(Income_Statement!G8=0,NA(),Income_Statement!G8) -> 1900000
B14: Variable | C14: =C9 -> 46023 | D14: =D9 -> 46388 | E14: =E9 -> 46753 | F14: =F9 -> 47119 | G14: =G9 -> 47484
B15: EBITDA | C15: =Income_Statement!C23 -> 927000 | D15: =Income_Statement!D23 -> 2439796 | E15: =Income_Statement!E23 -> 4797560.9 | F15: =Income_Statement!F23 -> 7372380.6 | G15: =Income_Statement!G23 -> 10234745
B16: Net Income | C16: =Income_Statement!C36 -> 48712.98 | D16: =Income_Statement!D36 -> 548169.15 | E16: =Income_Statement!E36 -> 1203236.3 | F16: =Income_Statement!F36 -> 1586955.7 | G16: =Income_Statement!G36 -> 1214294.1
B19: Variable | C19: =C14 -> 46023 | D19: =D14 -> 46388 | E19: =E14 -> 46753 | F19: =F14 -> 47119 | G19: =G14 -> 47484
B20: Gross Margin (%) | C20: =Income_Statement!C16 -> 0.8943787 | D20: =Income_Statement!D16 -> 0.88838171 | E20: =Income_Statement!E16 -> 0.88447076 | F20: =Income_Statement!F16 -> 0.87966271 | G20: =Income_Statement!G16 -> 0.87401079
B21: EBITDA Margin (%) | C21: =Income_Statement!C24 -> 0.54852071 | D21: =Income_Statement!D24 -> 0.68415382 | E21: =Income_Statement!E24 -> 0.74102345 | F21: =Income_Statement!F24 -> 0.7609704 | G21: =Income_Statement!G24 -> 0.76900683
B22: Net Margin (%) | C22: =Income_Statement!C37 -> 0.028824249 | D22: =Income_Statement!D37 -> 0.1537145 | E22: =Income_Statement!E37 -> 0.18584992 | F22: =Income_Statement!F37 -> 0.16380412 | G22: =Income_Statement!G37 -> 0.091238275
B24: Cumulative Capex Funding Sources | C24: Total
B25: Asset debt draw | C25: =SUM('Deploymnet_&_CAPEX_Schedule'!C14:G14) -> 44850000
B26: Equity / cash funded | C26: =SUM('Deploymnet_&_CAPEX_Schedule'!C15:G15) -> 29900000
B27: ITC cash credit (Direct Pay) | C27: =SUM('Deploymnet_&_CAPEX_Schedule'!C17:G17) -> 29900000

Sheet Assumptions
B2: Assumptions
B4: Select Model Start Year >>> | C4: 46023
B6: Metric | C6: Unit | D6: Year 1 | E6: Year 2 | F6: Year 3 | G6: Year 4 | H6: Year 5
D7: =C4 -> 46023 | E7: =DATE(YEAR(D7)+1,MONTH(D7),DAY(D7)) -> 46388 | F7: =DATE(YEAR(E7)+1,MONTH(E7),DAY(E7)) -> 46753 | G7: =DATE(YEAR(F7)+1,MONTH(F7),DAY(F7)) -> 47119 | H7: =DATE(YEAR(G7)+1,MONTH(G7),DAY(G7)) -> 47484
B9: Deployment Plan
B10: Systems installed (New) | C10: Count | D10: 10 | E10: 10 | F10: 15 | G10: 15 | H10: 15
B11: Cumulative systems installed | C11: Count in years | D11: =D10 -> 10 | E11: =D11+E10 -> 20 | F11: =E11+F10 -> 35 | G11: =F11+G10 -> 50 | H11: =G11+H10 -> 65
B13: Unit Economics (Per System)
B14: System size — solar (kW DC) | C14: kW | D14: 500 | E14: =D14 -> 500 | F14: =E14 -> 500 | G14: =F14 -> 500 | H14: =G14 -> 500
B15: System size — battery storage (kWh) | C15: kWh | D15: 1000 | E15: =D15 -> 1000 | F15: =E15 -> 1000 | G15: =F15 -> 1000 | H15: =G15 -> 1000
B16: Cost decline / learning curve (%/yr) | C16: % | D16: 0
B17: Installed cost per system (blended, $) | C17: $ | D17: 1150000 | E17: =D17 -> 1150000 | F17: =E17 -> 1150000 | G17: =F17 -> 1150000 | H17: =G17 -> 1150000
B18: Annual generation per system (Yr-1 of life) | C18: kWh | D18: 700000 | E18: =D18 -> 700000 | F18: =E18 -> 700000 | G18: =F18 -> 700000 | H18: =G18 -> 700000
B19: Solar/BESS output degradation (%/yr) | C19: % | D19: 0.005 | E19: =D19 -> 0.005 | F19: =E19 -> 0.005 | G19: =F19 -> 0.005 | H19: =G19 -> 0.005
B20: PPA rate at contract signing ($/kWh) | C20: $/kWh | D20: 0.17 | E20: =D20 -> 0.17 | F20: =E20 -> 0.17 | G20: =F20 -> 0.17 | H20: =G20 -> 0.17
B21: PPA annual price escalator (%/yr) | C21: % | D21: 0.025 | E21: =D21 -> 0.025 | F21: =E21 -> 0.025 | G21: =F21 -> 0.025 | H21: =G21 -> 0.025
B22: Grid services / demand response revenue | C22: $/sys/yr | D22: 50000 | E22: =D22 -> 50000 | F22: =E22 -> 50000 | G22: =F22 -> 50000 | H22: =G22 -> 50000
B23: O&M / monitoring (% of PPA revenue) | C23: % | D23: 0.15 | E23: =D23 -> 0.15 | F23: =E23 -> 0.15 | G23: =F23 -> 0.15 | H23: =G23 -> 0.15
B25: Saas Licensing (Asset-Light)
B26: New SaaS ARR signed in year | C26: $ | D26: 0 | E26: 150000 | F26: 300000 | G26: 550000 | H26: 900000
B27: Cumulative SaaS ARR | C27: $ | D27: 0 | E27: =E26 -> 150000 | F27: =E27+F26 -> 450000 | G27: =F27+G26 -> 1000000 | H27: =G27+H26 -> 1900000
B28: SaaS gross margin | C28: % | D28: 0.75 | E28: =D28 -> 0.75 | F28: =E28 -> 0.75 | G28: =F28 -> 0.75 | H28: =G28 -> 0.75
B30: Project Financing Structure
B31: Asset debt facility (% of system capex) | C31: % | D31: 0.6 | E31: =D31 -> 0.6 | F31: =E31 -> 0.6 | G31: =F31 -> 0.6 | H31: =G31 -> 0.6
B32: Equity / cash on hand (% of system capex) | C32: % | D32: =1-D31 -> 0.4 | E32: =D32 -> 0.4 | F32: =E32 -> 0.4 | G32: =F32 -> 0.4 | H32: =G32 -> 0.4
B33: Asset debt interest rate (fixed) | C33: % | D33: 0.075 | E33: =D33 -> 0.075 | F33: =E33 -> 0.075 | G33: =F33 -> 0.075 | H33: =G33 -> 0.075
B34: Asset debt tenor / amortization | C34: yrs | D34: 11 | E34: =D34 -> 11 | F34: =E34 -> 11 | G34: =F34 -> 11 | H34: =G34 -> 11
B35: ITC rate — Direct Pay (blended, base + adders) | C35: % | D35: 0.4 | E35: =D35 -> 0.4 | F35: =E35 -> 0.4 | G35: =F35 -> 0.4 | H35: =G35 -> 0.4
B36: ITC depreciable basis reduction (% of ITC) | C36: % | D36: 0.5 | E36: =D36 -> 0.5 | F36: =E36 -> 0.5 | G36: =F36 -> 0.5 | H36: =G36 -> 0.5
B38: Depreciation & Tax (Current Law, Post-Obbba — Enacted 7/4/2025)
B39: Bonus depreciation % (placed in service after 1/19/25) | C39: % | D39: 1 | E39: =D39 -> 1 | F39: =E39 -> 1 | G39: =F39 -> 1 | H39: =G39 -> 1
B40: Federal corporate tax rate | C40: % | D40: 0.21 | E40: =D40 -> 0.21 | F40: =E40 -> 0.21 | G40: =F40 -> 0.21 | H40: =G40 -> 0.21
B41: State corporate tax rate | C41: % | D41: 0.044 | E41: =D41 -> 0.044 | F41: =E41 -> 0.044 | G41: =F41 -> 0.044 | H41: =G41 -> 0.044
B42: Blended effective tax rate | C42: % | D42: =D40+D41*(1-D40) -> 0.24476 | E42: =D42 -> 0.24476 | F42: =E42 -> 0.24476 | G42: =F42 -> 0.24476 | H42: =G42 -> 0.24476
B43: NOL utilization limit (% of taxable income) | C43: % | D43: 0.8 | E43: =D43 -> 0.8 | F43: =E43 -> 0.8 | G43: =F43 -> 0.8 | H43: =G43 -> 0.8
B45: Corporate Operating Expenses (Below Project Level)
B46: R&D / software engineering — Year 1 | C46: $ | D46: 350000
B47: R&D growth rate (%/yr) | C47: % | D47: 0.1 | E47: =D47 -> 0.1 | F47: =E47 -> 0.1 | G47: =F47 -> 0.1 | H47: =G47 -> 0.1
B48: Sales & business development — Year 1 | C48: $ | D48: 150000
B49: S&BD growth rate (%/yr) | C49: % | D49: 0.1 | E49: =D49 -> 0.1 | F49: =E49 -> 0.1 | G49: =F49 -> 0.1 | H49: =G49 -> 0.1
...

Sheet Dashboard
B2: Solistice Renewable Energy
B3: Executive Dashboard
B5: Key Performance Indicators — 5 Year Average (Except Sys. Deployed)
B15: 5-Year Financial Summary
B17: Metric | C17: =Assumptions!D7 -> 46023 | D17: =Assumptions!E7 -> 46388 | E17: =Assumptions!F7 -> 46753 | F17: =Assumptions!G7 -> 47119 | G17: =Assumptions!H7 -> 47484
B18: Total revenue | C18: =Income_Statement!C9 -> 1690000 | D18: =Income_Statement!D9 -> 3566151.2 | E18: =Income_Statement!E9 -> 6474236.3 | F18: =Income_Statement!F9 -> 9688130.6 | G18: =Income_Statement!G9 -> 13309043
B19: Gross margin % | C19: =Income_Statement!C16 -> 0.8943787 | D19: =Income_Statement!D16 -> 0.88838171 | E19: =Income_Statement!E16 -> 0.88447076 | F19: =Income_Statement!F16 -> 0.87966271 | G19: =Income_Statement!G16 -> 0.87401079
B20: EBITDA margin % | C20: =Income_Statement!C24 -> 0.54852071 | D20: =Income_Statement!D24 -> 0.68415382 | E20: =Income_Statement!E24 -> 0.74102345 | F20: =Income_Statement!F24 -> 0.7609704 | G20: =Income_Statement!G24 -> 0.76900683
B21: Net income | C21: =Income_Statement!C36 -> 48712.98 | D21: =Income_Statement!D36 -> 548169.15 | E21: =Income_Statement!E36 -> 1203236.3 | F21: =Income_Statement!F36 -> 1586955.7 | G21: =Income_Statement!G36 -> 1214294.1
B22: Net margin % | C22: =Income_Statement!C37 -> 0.028824249 | D22: =Income_Statement!D37 -> 0.1537145 | E22: =Income_Statement!E37 -> 0.18584992 | F22: =Income_Statement!F37 -> 0.16380412 | G22: =Income_Statement!G37 -> 0.091238275
B23: Ending cash balance | C23: =Balance_Sheet!D12 -> 11891809 | D23: =Balance_Sheet!E12 -> 12122285 | E23: =Balance_Sheet!F12 -> 12751058 | F23: =Balance_Sheet!G12 -> 13505529 | G23: =Balance_Sheet!H12 -> 13566696
B24: Net PP&E | C24: =Balance_Sheet!D15 -> 6555000 | D24: =Balance_Sheet!E15 -> 12765000 | E24: =Balance_Sheet!F15 -> 21907500 | F24: =Balance_Sheet!G15 -> 30532500 | G24: =Balance_Sheet!H15 -> 38640000
B25: Cumulative systems deployed | C25: ='Deploymnet_&_CAPEX_Schedule'!C6 -> 10 | D25: ='Deploymnet_&_CAPEX_Schedule'!D6 -> 20 | E25: ='Deploymnet_&_CAPEX_Schedule'!E6 -> 35 | F25: ='Deploymnet_&_CAPEX_Schedule'!F6 -> 50 | G25: ='Deploymnet_&_CAPEX_Schedule'!G6 -> 65
B26: Cumulative gross capex | C26: ='Deploymnet_&_CAPEX_Schedule'!C11 -> 11500000 | D26: ='Deploymnet_&_CAPEX_Schedule'!D11 -> 23000000 | E26: ='Deploymnet_&_CAPEX_Schedule'!E11 -> 40250000 | F26: ='Deploymnet_&_CAPEX_Schedule'!F11 -> 57500000 | G26: ='Deploymnet_&_CAPEX_Schedule'!G11 -> 74750000
B27: Cumulative ITC cash credit | C27: ='Deploymnet_&_CAPEX_Schedule'!C17 -> 4600000 | D27: =C27+'Deploymnet_&_CAPEX_Schedule'!D17 -> 9200000 | E27: =D27+'Deploymnet_&_CAPEX_Schedule'!E17 -> 16100000 | F27: =E27+'Deploymnet_&_CAPEX_Schedule'!F17 -> 23000000 | G27: =F27+'Deploymnet_&_CAPEX_Schedule'!G17 -> 29900000
B29: Visual Analysis

Sheet Income_Statement
B2: Consolidated Income Statement
B3: $ in whole dollars unless noted
B4: ($, unless noted) | C4: =Assumptions!D7 -> 46023 | D4: =Assumptions!E7 -> 46388 | E4: =Assumptions!F7 -> 46753 | F4: =Assumptions!G7 -> 47119 | G4: =Assumptions!H7 -> 47484
B6: PPA revenue | C6: =Revenue_Build!C35 -> 1190000 | D6: =Revenue_Build!D35 -> 2403651.2 | E6: =Revenue_Build!E35 -> 4236423.8 | F6: =Revenue_Build!F35 -> 6105622.7 | G6: =Revenue_Build!G35 -> 8011972
B7: Grid services / demand response revenue | C7: =Revenue_Build!C36 -> 500000 | D7: =Revenue_Build!D36 -> 1012500 | E7: =Revenue_Build!E36 -> 1787812.5 | F7: =Revenue_Build!F36 -> 2582507.8 | G7: =Revenue_Build!G36 -> 3397070.5
B8: SaaS licensing revenue | C8: =Revenue_Build!C40 -> 0 | D8: =Revenue_Build!D40 -> 150000 | E8: =Revenue_Build!E40 -> 450000 | F8: =Revenue_Build!F40 -> 1000000 | G8: =Revenue_Build!G40 -> 1900000
B9: Total revenue | C9: =SUM(C6:C8) -> 1690000 | D9: =SUM(D6:D8) -> 3566151.2 | E9: =SUM(E6:E8) -> 6474236.3 | F9: =SUM(F6:F8) -> 9688130.6 | G9: =SUM(G6:G8) -> 13309043
B11: O&M / monitoring cost | C11: =Revenue_Build!C37 -> 178500 | D11: =Revenue_Build!D37 -> 360547.69 | E11: =Revenue_Build!E37 -> 635463.57 | F11: =Revenue_Build!F37 -> 915843.41 | G11: =Revenue_Build!G37 -> 1201795.8
B12: SaaS cost of revenue | C12: =Revenue_Build!C41 -> 0 | D12: =Revenue_Build!D41 -> 37500 | E12: =Revenue_Build!E41 -> 112500 | F12: =Revenue_Build!F41 -> 250000 | G12: =Revenue_Build!G41 -> 475000
B13: Total cost of revenue | C13: =SUM(C11:C12) -> 178500 | D13: =SUM(D11:D12) -> 398047.69 | E13: =SUM(E11:E12) -> 747963.57 | F13: =SUM(F11:F12) -> 1165843.4 | G13: =SUM(G11:G12) -> 1676795.8
B15: Gross profit | C15: =C9-C13 -> 1511500 | D15: =D9-D13 -> 3168103.6 | E15: =E9-E13 -> 5726272.7 | F15: =F9-F13 -> 8522287.1 | G15: =G9-G13 -> 11632247
B16: Gross margin % | C16: =C15/C9 -> 0.8943787 | D16: =D15/D9 -> 0.88838171 | E16: =E15/E9 -> 0.88447076 | F16: =F15/F9 -> 0.87966271 | G16: =G15/G9 -> 0.87401079
B18: R&D / software engineering | C18: =Assumptions!$D$46*(1+Assumptions!D47)^0 -> 350000 | D18: =Assumptions!$D$46*(1+Assumptions!E47)^1 -> 385000 | E18: =Assumptions!$D$46*(1+Assumptions!F47)^2 -> 423500 | F18: =Assumptions!$D$46*(1+Assumptions!G47)^3 -> 465850 | G18: =Assumptions!$D$46*(1+Assumptions!H47)^4 -> 512435
B19: Sales & business development | C19: =Assumptions!$D$48*(1+Assumptions!D49)^0 -> 150000 | D19: =Assumptions!$D$48*(1+Assumptions!E49)^1 -> 165000 | E19: =Assumptions!$D$48*(1+Assumptions!F49)^2 -> 181500 | F19: =Assumptions!$D$48*(1+Assumptions!G49)^3 -> 199650 | G19: =Assumptions!$D$48*(1+Assumptions!H49)^4 -> 219615
B20: General & administrative | C20: =C9*Assumptions!D50 -> 84500 | D20: =D9*Assumptions!E50 -> 178307.56 | E20: =E9*Assumptions!F50 -> 323711.82 | F20: =F9*Assumptions!G50 -> 484406.53 | G20: =G9*Assumptions!H50 -> 665452.13
B21: Total operating expenses | C21: =SUM(C18:C20) -> 584500 | D21: =SUM(D18:D20) -> 728307.56 | E21: =SUM(E18:E20) -> 928711.82 | F21: =SUM(F18:F20) -> 1149906.5 | G21: =SUM(G18:G20) -> 1397502.1
B23: EBITDA | C23: =C15-C21 -> 927000 | D23: =D15-D21 -> 2439796 | E23: =E15-E21 -> 4797560.9 | F23: =F15-F21 -> 7372380.6 | G23: =G15-G21 -> 10234745
B24: EBITDA margin % | C24: =C23/C9 -> 0.54852071 | D24: =D23/D9 -> 0.68415382 | E24: =E23/E9 -> 0.74102345 | F24: =F23/F9 -> 0.7609704 | G24: =G23/G9 -> 0.76900683
B26: Depreciation & amortization | C26: =Depreciation_ITC!C35 -> 345000 | D26: =Depreciation_ITC!D35 -> 690000 | E26: =Depreciation_ITC!E35 -> 1207500 | F26: =Depreciation_ITC!F35 -> 1725000 | G26: =Depreciation_ITC!G35 -> 2242500
B27: EBIT (operating income) | C27: =C23-C26 -> 582000 | D27: =D23-D26 -> 1749796 | E27: =E23-E26 -> 3590060.9 | F27: =F23-F26 -> 5647380.6 | G27: =G23-G26 -> 7992244.6
B29: Interest expense — asset debt | C29: =Debt_Schedule!C46 -> 517500 | D29: =Debt_Schedule!D46 -> 1003071.6 | E29: =Debt_Schedule!E46 -> 1713070 | F29: =Debt_Schedule!F46 -> 2370207 | G29: =Debt_Schedule!G46 -> 2970517.8
B30: Pre-tax income (EBT) | C30: =C27-C29 -> 64500 | D30: =D27-D29 -> 746724.44 | E30: =E27-E29 -> 1876990.9 | F30: =F27-F29 -> 3277173.6 | G30: =G27-G29 -> 5021726.8
B31: NOL carryforward, beginning balance | C31: 0 | D31: =C34 -> -64500 | E31: =D34 -> -875724.44 | F31: =E34 -> -3628439.8 | G31: =F34 -> -10534053
B32: NOL utilized against current-yr income | C32: =IF(C30>0,MIN(C31,C30*Assumptions!D43),0) -> 0 | D32: =IF(D30>0,MIN(D31,D30*Assumptions!E43),0) -> -64500 | E32: =IF(E30>0,MIN(E31,E30*Assumptions!F43),0) -> -875724.44 | F32: =IF(F30>0,MIN(F31,F30*Assumptions!G43),0) -> -3628439.8 | G32: =IF(G30>0,MIN(G31,G30*Assumptions!H43),0) -> -10534053
B33: Taxable income (after NOL) | C33: =MAX(0,C30-C32) -> 64500 | D33: =MAX(0,D30-D32) -> 811224.44 | E33: =MAX(0,E30-E32) -> 2752715.3 | F33: =MAX(0,F30-F32) -> 6905613.4 | G33: =MAX(0,G30-G32) -> 15555780
B34: NOL carryforward, ending balance | C34: =C31-C33+MAX(0,-C30) -> -64500 | D34: =D31-D33+MAX(0,-D30) -> -875724.44 | E34: =E31-E33+MAX(0,-E30) -> -3628439.8 | F34: =F31-F33+MAX(0,-F30) -> -10534053 | G34: =G31-G33+MAX(0,-G30) -> -26089833
B35: Income tax provision | C35: =C33*Assumptions!D42 -> 15787.02 | D35: =D33*Assumptions!E42 -> 198555.29 | E35: =E33*Assumptions!F42 -> 673754.61 | F35: =F33*Assumptions!G42 -> 1690217.9 | G35: =G33*Assumptions!H42 -> 3807432.7
B36: Net income | C36: =C30-C35 -> 48712.98 | D36: =D30-D35 -> 548169.15 | E36: =E30-E35 -> 1203236.3 | F36: =F30-F35 -> 1586955.7 | G36: =G30-G35 -> 1214294.1
B37: Net margin % | C37: =C36/C9 -> 0.028824249 | D37: =D36/D9 -> 0.1537145 | E37: =E36/E9 -> 0.18584992 | F37: =F36/F9 -> 0.16380412 | G37: =G36/G9 -> 0.091238275

Sheet Balance_Sheet
B2: Consolidated Balance Sheet
B3: $ in whole dollars
B4: ($, unless noted) | C4: Opening | D4: =Assumptions!D7 -> 46023 | E4: =Assumptions!E7 -> 46388 | F4: =Assumptions!F7 -> 46753 | G4: =Assumptions!G7 -> 47119 | H4: =Assumptions!H7 -> 47484
B6: Opening Balance
B7: Opening cash balance | C7: 2000000
B8: Paid-in capital, prior rounds (SAFE + Seed) | C8: 3500000
B9: Accumulated deficit, entering FY2026 | C9: -1500000
B11: Assets
B12: Cash & cash equivalents | D12: =Cash_Flow!C26 -> 11891809 | E12: =Cash_Flow!D26 -> 12122285 | F12: =Cash_Flow!E26 -> 12751058 | G12: =Cash_Flow!F26 -> 13505529 | H12: =Cash_Flow!G26 -> 13566696
B13: Accounts receivable | D13: =Income_Statement!C9/365*(Assumptions!D53) -> 138904.11 | E13: =Income_Statement!D9/365*(Assumptions!E53) -> 293108.32 | F13: =Income_Statement!E9/365*(Assumptions!F53) -> 532129.01 | G13: =Income_Statement!F9/365*(Assumptions!G53) -> 796284.7 | H13: =Income_Statement!G9/365*(Assumptions!H53) -> 1093893.9
B14: Change in AR (vs. prior year) | D14: =D13-0 -> 138904.11 | E14: =E13-D13 -> 154204.21 | F14: =F13-E13 -> 239020.69 | G14: =G13-F13 -> 264155.69 | H14: =H13-G13 -> 297609.2
B15: Property, plant & equipment, net | D15: =0+('Deploymnet_&_CAPEX_Schedule'!C10-'Deploymnet_&_CAPEX_Schedule'!C17)-Income_Statement!C26 -> 6555000 | E15: =D15+('Deploymnet_&_CAPEX_Schedule'!D10-'Deploymnet_&_CAPEX_Schedule'!D17)-Income_Statement!D26 -> 12765000 | F15: =E15+('Deploymnet_&_CAPEX_Schedule'!E10-'Deploymnet_&_CAPEX_Schedule'!E17)-Income_Statement!E26 -> 21907500 | G15: =F15+('Deploymnet_&_CAPEX_Schedule'!F10-'Deploymnet_&_CAPEX_Schedule'!F17)-Income_Statement!F26 -> 30532500 | H15: =G15+('Deploymnet_&_CAPEX_Schedule'!G10-'Deploymnet_&_CAPEX_Schedule'!G17)-Income_Statement!G26 -> 38640000
B16: Total assets | D16: =D12+D13+D15 -> 18585713 | E16: =E12+E13+E15 -> 25180393 | F16: =F12+F13+F15 -> 35190687 | G16: =G12+G13+G15 -> 44834314 | H16: =H12+H13+H15 -> 53300590
B18: Liabilities
B19: Accounts payable | D19: =(Income_Statement!C13+Income_Statement!C21)/365*(Assumptions!D54) -> 62712.329 | E19: =(Income_Statement!D13+Income_Statement!D21)/365*(Assumptions!E54) -> 92577.144 | F19: =(Income_Statement!E13+Income_Statement!E21)/365*(Assumptions!F54) -> 137808.94 | G19: =(Income_Statement!F13+Income_Statement!F21)/365*(Assumptions!G54) -> 190335.61 | H19: =(Income_Statement!G13+Income_Statement!G21)/365*(Assumptions!H54) -> 252682.02
B20: Change in AP (vs. prior year) | D20: =D19-0 -> 62712.329 | E20: =E19-D19 -> 29864.815 | F20: =F19-E19 -> 45231.792 | G20: =G19-F19 -> 52526.675 | H20: =H19-G19 -> 62346.41
B21: Asset debt outstanding | D21: =Debt_Schedule!C49 -> 6474287.4 | E21: =Debt_Schedule!D49 -> 12490934 | F21: =Debt_Schedule!E49 -> 21252760 | G21: =Debt_Schedule!F49 -> 29256904 | H21: =Debt_Schedule!G49 -> 36446540
B22: Total liabilities | D22: =D19+D21 -> 6536999.8 | E22: =E19+E21 -> 12583511 | F22: =F19+F21 -> 21390569 | G22: =G19+G21 -> 29447240 | H22: =H19+H21 -> 36699222
B24: Stockholders' Equity
B25: Paid-in capital | D25: =$C$8+Cap_Table!$C$6 -> 13500000 | E25: =$C$8+Cap_Table!$C$6 -> 13500000 | F25: =$C$8+Cap_Table!$C$6 -> 13500000 | G25: =$C$8+Cap_Table!$C$6 -> 13500000 | H25: =$C$8+Cap_Table!$C$6 -> 13500000
B26: Accumulated deficit / retained earnings | D26: =$C$9+Income_Statement!C36 -> -1451287 | E26: =D26+Income_Statement!D36 -> -903117.87 | F26: =E26+Income_Statement!E36 -> 300118.41 | G26: =F26+Income_Statement!F36 -> 1887074.1 | H26: =G26+Income_Statement!G36 -> 3101368.2
B27: Total stockholders' equity | D27: =SUM(D25:D26) -> 12048713 | E27: =SUM(E25:E26) -> 12596882 | F27: =SUM(F25:F26) -> 13800118 | G27: =SUM(G25:G26) -> 15387074 | H27: =SUM(H25:H26) -> 16601368
B29: Total liabilities & equity | D29: =SUM(D22,D27) -> 18585713 | E29: =SUM(E22,E27) -> 25180393 | F29: =SUM(F22,F27) -> 35190687 | G29: =SUM(G22,G27) -> 44834314 | H29: =SUM(H22,H27) -> 53300590
B31: Balance Check | C31: =C16-C29 -> 0 | D31: =D16-D29 -> 0 | E31: =E16-E29 -> 0 | F31: =F16-F29 -> 0 | G31: =G16-G29 -> 0 | H31: =H16-H29 -> 0

Sheet Cash_Flow
B2: Consolidated Statement of Cash Flows
B3: Indirect method | $ in whole dollars
C4: =Assumptions!D7 -> 46023 | D4: =Assumptions!E7 -> 46388 | E4: =Assumptions!F7 -> 46753 | F4: =Assumptions!G7 -> 47119 | G4: =Assumptions!H7 -> 47484
B6: Cash Flow From Operating Activities
B7: Net income | C7: =Income_Statement!C36 -> 48712.98 | D7: =Income_Statement!D36 -> 548169.15 | E7: =Income_Statement!E36 -> 1203236.3 | F7: =Income_Statement!F36 -> 1586955.7 | G7: =Income_Statement!G36 -> 1214294.1
B8: + Depreciation & amortization | C8: =Income_Statement!C26 -> 345000 | D8: =Income_Statement!D26 -> 690000 | E8: =Income_Statement!E26 -> 1207500 | F8: =Income_Statement!F26 -> 1725000 | G8: =Income_Statement!G26 -> 2242500
B9: (Increase) in accounts receivable | C9: =-Balance_Sheet!D14 -> -138904.11 | D9: =-Balance_Sheet!E14 -> -154204.21 | E9: =-Balance_Sheet!F14 -> -239020.69 | F9: =-Balance_Sheet!G14 -> -264155.69 | G9: =-Balance_Sheet!H14 -> -297609.2
B10: Increase in accounts payable | C10: =Balance_Sheet!D20 -> 62712.329 | D10: =Balance_Sheet!E20 -> 29864.815 | E10: =Balance_Sheet!F20 -> 45231.792 | F10: =Balance_Sheet!G20 -> 52526.675 | G10: =Balance_Sheet!H20 -> 62346.41
B11: Cash flow from operations | C11: =SUM(C7:C10) -> 317521.2 | D11: =SUM(D7:D10) -> 1113829.8 | E11: =SUM(E7:E10) -> 2216947.4 | F11: =SUM(F7:F10) -> 3100326.7 | G11: =SUM(G7:G10) -> 3221531.3
B13: Cash Flow From Investing Activities
B14: Capex — new solar + storage systems | C14: =-'Deploymnet_&_CAPEX_Schedule'!C10 -> -11500000 | D14: =-'Deploymnet_&_CAPEX_Schedule'!D10 -> -11500000 | E14: =-'Deploymnet_&_CAPEX_Schedule'!E10 -> -17250000 | F14: =-'Deploymnet_&_CAPEX_Schedule'!F10 -> -17250000 | G14: =-'Deploymnet_&_CAPEX_Schedule'!G10 -> -17250000
B15: + ITC cash credit received (Direct Pay) | C15: ='Deploymnet_&_CAPEX_Schedule'!C17 -> 4600000 | D15: ='Deploymnet_&_CAPEX_Schedule'!D17 -> 4600000 | E15: ='Deploymnet_&_CAPEX_Schedule'!E17 -> 6900000 | F15: ='Deploymnet_&_CAPEX_Schedule'!F17 -> 6900000 | G15: ='Deploymnet_&_CAPEX_Schedule'!G17 -> 6900000
B16: Cash flow from investing | C16: =SUM(C14:C15) -> -6900000 | D16: =SUM(D14:D15) -> -6900000 | E16: =SUM(E14:E15) -> -10350000 | F16: =SUM(F14:F15) -> -10350000 | G16: =SUM(G14:G15) -> -10350000
B18: Cash Flow From Financing Activities
B19: Series A proceeds (net) | C19: =Cap_Table!C6 -> 10000000
B20: + Asset debt drawn | C20: =Debt_Schedule!C48 -> 6900000 | D20: =Debt_Schedule!D48 -> 6900000 | E20: =Debt_Schedule!E48 -> 10350000 | F20: =Debt_Schedule!F48 -> 10350000 | G20: =Debt_Schedule!G48 -> 10350000
B21: - Asset debt principal repayment | C21: =-Debt_Schedule!C47 -> -425712.57 | D21: =-Debt_Schedule!D47 -> -883353.58 | E21: =-Debt_Schedule!E47 -> -1588174 | F21: =-Debt_Schedule!F47 -> -2345855.9 | G21: =-Debt_Schedule!G47 -> -3160363.9
B22: Cash flow from financing | C22: =SUM(C19:C21) -> 16474287 | D22: =SUM(D19:D21) -> 6016646.4 | E22: =SUM(E19:E21) -> 8761826 | F22: =SUM(F19:F21) -> 8004144.1 | G22: =SUM(G19:G21) -> 7189636.1
B24: Net change in cash | C24: =SUM(C11,C16,C22) -> 9891808.6 | D24: =SUM(D11,D16,D22) -> 230476.17 | E24: =SUM(E11,E16,E22) -> 628773.44 | F24: =SUM(F11,F16,F22) -> 754470.82 | G24: =SUM(G11,G16,G22) -> 61167.388
B25: Cash, beginning of year | C25: =Balance_Sheet!C7 -> 2000000 | D25: =C26 -> 11891809 | E25: =D26 -> 12122285 | F25: =E26 -> 12751058 | G25: =F26 -> 13505529
B26: Cash, end of year | C26: =SUM(C24:C25) -> 11891809 | D26: =SUM(D24:D25) -> 12122285 | E26: =SUM(E24:E25) -> 12751058 | F26: =SUM(F24:F25) -> 13505529 | G26: =SUM(G24:G25) -> 13566696

Sheet Deploymnet_&_CAPEX_Schedule
B2: Deployment & CAPEX Schedule
B3: Metrics | C3: =Assumptions!D7 -> 46023 | D3: =Assumptions!E7 -> 46388 | E3: =Assumptions!F7 -> 46753 | F3: =Assumptions!G7 -> 47119 | G3: =Assumptions!H7 -> 47484
B4: System Build-Out
B5: New systems installed (vintage) | C5: =Assumptions!D10 -> 10 | D5: =Assumptions!E10 -> 10 | E5: =Assumptions!F10 -> 15 | F5: =Assumptions!G10 -> 15 | G5: =Assumptions!H10 -> 15
B6: Cumulative systems installed | C6: =Assumptions!D11 -> 10 | D6: =Assumptions!E11 -> 20 | E6: =Assumptions!F11 -> 35 | F6: =Assumptions!G11 -> 50 | G6: =Assumptions!H11 -> 65
B7: Installed cost per system ($) | C7: =Assumptions!D17 -> 1150000 | D7: =Assumptions!E17 -> 1150000 | E7: =Assumptions!F17 -> 1150000 | F7: =Assumptions!G17 -> 1150000 | G7: =Assumptions!H17 -> 1150000
B9: Capital Expenditure
B10: Gross capex — new systems ($) | C10: =C7*C5 -> 11500000 | D10: =D7*D5 -> 11500000 | E10: =E7*E5 -> 17250000 | F10: =F7*F5 -> 17250000 | G10: =G7*G5 -> 17250000
B11: Cumulative gross capex ($) | C11: =C10 -> 11500000 | D11: =C11+D10 -> 23000000 | E11: =D11+E10 -> 40250000 | F11: =E11+F10 -> 57500000 | G11: =F11+G10 -> 74750000
B13: Sources Of Funds
B14: Asset debt draw ($) | C14: =C10*Assumptions!D31 -> 6900000 | D14: =D10*Assumptions!E31 -> 6900000 | E14: =E10*Assumptions!F31 -> 10350000 | F14: =F10*Assumptions!G31 -> 10350000 | G14: =G10*Assumptions!H31 -> 10350000
B15: Equity / cash funded ($) | C15: =C10*Assumptions!D32 -> 4600000 | D15: =D10*Assumptions!E32 -> 4600000 | E15: =E10*Assumptions!F32 -> 6900000 | F15: =F10*Assumptions!G32 -> 6900000 | G15: =G10*Assumptions!H32 -> 6900000
B16: ITC eligible basis ($, = gross capex) | C16: =C10 -> 11500000 | D16: =D10 -> 11500000 | E16: =E10 -> 17250000 | F16: =F10 -> 17250000 | G16: =G10 -> 17250000
B17: ITC cash credit — Direct Pay ($) | C17: =C16*Assumptions!D35 -> 4600000 | D17: =D16*Assumptions!E35 -> 4600000 | E17: =E16*Assumptions!F35 -> 6900000 | F17: =F16*Assumptions!G35 -> 6900000 | G17: =G16*Assumptions!H35 -> 6900000
B18: Net equity capex requirement, post-ITC ($)
B20: Tax Depreciable Basis — Informational (Irc Sec. 50(C))
B21: Tax depreciable basis, post 50(c) reduction ($) | C21: =C10-C17*Assumptions!D36 -> 9200000 | D21: =D10-D17*Assumptions!E36 -> 9200000 | E21: =E10-E17*Assumptions!F36 -> 13800000 | F21: =F10-F17*Assumptions!G36 -> 13800000 | G21: =G10-G17*Assumptions!H36 -> 13800000
B22: Book depreciable basis, net of full ITC ($) | C22: =C10-C17 -> 6900000 | D22: =D10-D17 -> 6900000 | E22: =E10-E17 -> 10350000 | F22: =F10-F17 -> 10350000 | G22: =G10-G17 -> 10350000

Sheet Debt_Schedule
B2: Asset Debt Schedule — Vintage Amortization
B4: Vintage | C4: =Assumptions!D7 -> 46023 | D4: =Assumptions!E7 -> 46388 | E4: =Assumptions!F7 -> 46753 | F4: =Assumptions!G7 -> 47119 | G4: =Assumptions!H7 -> 47484
B5: Vintage 1 — Systems Installed FY2026
B6: Debt drawn at COD ($) | C6: ='Deploymnet_&_CAPEX_Schedule'!C14 -> 6900000
B7: Annual debt service (level pmt, $) | C7: =-PMT(Assumptions!D33,Assumptions!D34,Debt_Schedule!C6) -> 943212.57
B8: Beginning balance ($) | C8: =C6 -> 6900000 | D8: =C11 -> 6474287.4 | E8: =D11 -> 6016646.4 | F8: =E11 -> 5524682.3 | G8: =F11 -> 4995820.9
B9: Interest expense ($) | C9: =C8*Assumptions!D33 -> 517500 | D9: =D8*Assumptions!E33 -> 485571.56 | E9: =E8*Assumptions!F33 -> 451248.48 | F9: =F8*Assumptions!G33 -> 414351.17 | G9: =G8*Assumptions!H33 -> 374686.57
B10: Principal repayment ($) | C10: =MIN($C$7-C9,$C$8) -> 425712.57 | D10: =MIN($C$7-D9,$C$8) -> 457641.01 | E10: =MIN($C$7-E9,$C$8) -> 491964.09 | F10: =MIN($C$7-F9,$C$8) -> 528861.39 | G10: =MIN($C$7-G9,$C$8) -> 568526
B11: Ending balance ($) | C11: =C8-C10 -> 6474287.4 | D11: =D8-D10 -> 6016646.4 | E11: =E8-E10 -> 5524682.3 | F11: =F8-F10 -> 4995820.9 | G11: =G8-G10 -> 4427294.9
B13: Vintage 2 — Systems Installed FY2027
B14: Debt drawn at COD ($) | D14: ='Deploymnet_&_CAPEX_Schedule'!D14 -> 6900000
B15: Annual debt service (level pmt, $) | D15: =-PMT(Assumptions!E33,Assumptions!E34,Debt_Schedule!D14) -> 943212.57
B16: Beginning balance ($) | C16: 0 | D16: =D14 -> 6900000 | E16: =D19 -> 6474287.4 | F16: =E19 -> 6016646.4 | G16: =F19 -> 5524682.3
B17: Interest expense ($) | C17: 0 | D17: =D16*Assumptions!E33 -> 517500 | E17: =E16*Assumptions!F33 -> 485571.56 | F17: =F16*Assumptions!G33 -> 451248.48 | G17: =G16*Assumptions!H33 -> 414351.17
B18: Principal repayment ($) | C18: 0 | D18: =MIN($D$15-D17,$D$15) -> 425712.57 | E18: =MIN($D$15-E17,$D$15) -> 457641.01 | F18: =MIN($D$15-F17,$D$15) -> 491964.09 | G18: =MIN($D$15-G17,$D$15) -> 528861.39
B19: Ending balance ($) | C19: 0 | D19: =D16-D18 -> 6474287.4 | E19: =E16-E18 -> 6016646.4 | F19: =F16-F18 -> 5524682.3 | G19: =G16-G18 -> 4995820.9
B21: Vintage 3 — Systems Installed FY2028
B22: Debt drawn at COD ($) | E22: ='Deploymnet_&_CAPEX_Schedule'!E14 -> 10350000
B23: Annual debt service (level pmt, $) | E23: =-PMT(Assumptions!F33,Assumptions!F34,Debt_Schedule!E22) -> 1414818.9
B24: Beginning balance ($) | C24: 0 | D24: 0 | E24: =E22 -> 10350000 | F24: =E27 -> 9711431.1 | G24: =F27 -> 9024969.6
B25: Interest expense ($) | C25: 0 | D25: 0 | E25: =E24*Assumptions!F33 -> 776250 | F25: =F24*Assumptions!G33 -> 728357.34 | G25: =G24*Assumptions!H33 -> 676872.72
B26: Principal repayment ($) | C26: 0 | D26: 0 | E26: =MIN($E$23-E25,$E$23) -> 638568.85 | F26: =MIN($E$23-F25,$E$23) -> 686461.52 | G26: =MIN($E$23-G25,$E$23) -> 737946.13
B27: Ending balance ($) | C27: 0 | D27: 0 | E27: =E24-E26 -> 9711431.1 | F27: =F24-F26 -> 9024969.6 | G27: =G24-G26 -> 8287023.5
B29: Vintage 4 — Systems Installed FY2029
B30: Debt drawn at COD ($) | F30: ='Deploymnet_&_CAPEX_Schedule'!F14 -> 10350000
B31: Annual debt service (level pmt, $) | F31: =-PMT(Assumptions!G33,Assumptions!G34,Debt_Schedule!F30) -> 1414818.9
B32: Beginning balance ($) | C32: 0 | D32: 0 | E32: 0 | F32: =F30 -> 10350000 | G32: =F35 -> 9711431.1
B33: Interest expense ($) | C33: 0 | D33: 0 | E33: 0 | F33: =F32*Assumptions!G33 -> 776250 | G33: =G32*Assumptions!H33 -> 728357.34
B34: Principal repayment ($) | C34: 0 | D34: 0 | E34: 0 | F34: =MIN($F$31-F33,$F$31) -> 638568.85 | G34: =MIN($F$31-G33,$F$31) -> 686461.52
B35: Ending balance ($) | C35: 0 | D35: 0 | E35: 0 | F35: =F32-F34 -> 9711431.1 | G35: =G32-G34 -> 9024969.6
B37: Vintage 5 — Systems Installed Fy2030
B38: Debt drawn at COD ($) | G38: ='Deploymnet_&_CAPEX_Schedule'!G14 -> 10350000
B39: Annual debt service (level pmt, $) | G39: =-PMT(Assumptions!H33,Assumptions!H34,Debt_Schedule!G38) -> 1414818.9
B40: Beginning balance ($) | C40: 0 | D40: 0 | E40: 0 | F40: 0 | G40: =G38 -> 10350000
B41: Interest expense ($) | C41: 0 | D41: 0 | E41: 0 | F41: 0 | G41: =G40*Assumptions!H33 -> 776250
B42: Principal repayment ($) | C42: 0 | D42: 0 | E42: 0 | F42: 0 | G42: =MIN($G$39-G41,$G$39) -> 638568.85
B43: Ending balance ($) | C43: 0 | D43: 0 | E43: 0 | F43: 0 | G43: =G40-G42 -> 9711431.1
B45: Consolidated — All Vintages
B46: Total interest expense ($) | C46: =SUM(C9,C17,C25,C33,C41) -> 517500 | D46: =SUM(D9,D17,D25,D33,D41) -> 1003071.6 | E46: =SUM(E9,E17,E25,E33,E41) -> 1713070 | F46: =SUM(F9,F17,F25,F33,F41) -> 2370207 | G46: =SUM(G9,G17,G25,G33,G41) -> 2970517.8
B47: Total principal repayment ($) | C47: =SUM(C10,C18,C26,C34,C42) -> 425712.57 | D47: =SUM(D10,D18,D26,D34,D42) -> 883353.58 | E47: =SUM(E10,E18,E26,E34,E42) -> 1588174 | F47: =SUM(F10,F18,F26,F34,F42) -> 2345855.9 | G47: =SUM(G10,G18,G26,G34,G42) -> 3160363.9
...

Sheet Depreciation_ITC
B2: Depreciation & ITC Schedule
B3: Vintage | C3: =Assumptions!D7 -> 46023 | D3: =Assumptions!E7 -> 46388 | E3: =Assumptions!F7 -> 46753 | F3: =Assumptions!G7 -> 47119 | G3: =Assumptions!H7 -> 47484
B4: Profitability and Return Ratios
B5: Book depreciable basis, net of full ITC ($) | C5: ='Deploymnet_&_CAPEX_Schedule'!C22 -> 6900000
B6: Useful life — straight-line (yrs) | C6: =Assumptions!D57 -> 20
B7: Straight-line depreciation expense ($/yr) | C7: =C5/C6 -> 345000
B8: Depreciation expense — this vintage ($) | C8: =C7 -> 345000 | D8: =C7 -> 345000 | E8: =C7 -> 345000 | F8: =C7 -> 345000 | G8: =C7 -> 345000
B10: Vintage 2 — Systems Installed FI2027
B11: Book depreciable basis, net of full ITC ($) | D11: ='Deploymnet_&_CAPEX_Schedule'!D22 -> 6900000
B12: Useful life — straight-line (yrs) | D12: =Assumptions!E57 -> 20
B13: Straight-line depreciation expense ($/yr) | D13: =D11/D12 -> 345000
B14: Depreciation expense — this vintage ($) | C14: 0 | D14: =D13 -> 345000 | E14: =D13 -> 345000 | F14: =D13 -> 345000 | G14: =D13 -> 345000
B16: Vintage 3 — Systems Installed FY2028
B17: Book depreciable basis, net of full ITC ($) | E17: ='Deploymnet_&_CAPEX_Schedule'!E22 -> 10350000
B18: Useful life — straight-line (yrs) | E18: =Assumptions!F57 -> 20
B19: Straight-line depreciation expense ($/yr) | E19: =E17/E18 -> 517500
B20: Depreciation expense — this vintage ($) | C20: 0 | D20: 0 | E20: =E19 -> 517500 | F20: =E19 -> 517500 | G20: =E19 -> 517500
B22: Vintage 4 — Systems Installed FY2029
B23: Book depreciable basis, net of full ITC ($) | F23: ='Deploymnet_&_CAPEX_Schedule'!F22 -> 10350000
B24: Useful life — straight-line (yrs) | F24: =Assumptions!G57 -> 20
B25: Straight-line depreciation expense ($/yr) | F25: =F23/F24 -> 517500
B26: Depreciation expense — this vintage ($) | C26: 0 | D26: 0 | E26: 0 | F26: =F25 -> 517500 | G26: =F25 -> 517500
B28: Vintage 5 — Systems Installed FY2030
B29: Book depreciable basis, net of full ITC ($) | G29: ='Deploymnet_&_CAPEX_Schedule'!G22 -> 10350000
B30: Useful life — straight-line (yrs) | G30: =Assumptions!H57 -> 20
B31: Straight-line depreciation expense ($/yr) | G31: =G29/G30 -> 517500
B32: Depreciation expense — this vintage ($) | C32: 0 | D32: 0 | E32: 0 | F32: 0 | G32: =G31 -> 517500
B34: Consolidated Depreciation
B35: Total depreciation expense ($) | C35: =SUM(C8,C14,C20,C26,C32) -> 345000 | D35: =SUM(D8,D14,D20,D26,D32) -> 690000 | E35: =SUM(E8,E14,E20,E26,E32) -> 1207500 | F35: =SUM(F8,F14,F20,F26,F32) -> 1725000 | G35: =SUM(G8,G14,G20,G26,G32) -> 2242500
B37: Itc — Direct Pay Cash Credit (From Deployment_Capex)
B38: ITC cash credit received in year ($) | C38: ='Deploymnet_&_CAPEX_Schedule'!C17 -> 4600000 | D38: ='Deploymnet_&_CAPEX_Schedule'!D17 -> 4600000 | E38: ='Deploymnet_&_CAPEX_Schedule'!E17 -> 6900000 | F38: ='Deploymnet_&_CAPEX_Schedule'!F17 -> 6900000 | G38: ='Deploymnet_&_CAPEX_Schedule'!G17 -> 6900000

Sheet Revenue_Build
B2: Revenue Build — By Vintage Cohort
B3: Vintage | C3: =Assumptions!D7 -> 46023 | D3: =Assumptions!E7 -> 46388 | E3: =Assumptions!F7 -> 46753 | F3: =Assumptions!G7 -> 47119 | G3: =Assumptions!H7 -> 47484
B4: Vintage 1 — Systems Installed Fy2026
B5: Generation (kWh) | C5: =Assumptions!D18*'Deploymnet_&_CAPEX_Schedule'!$C$5*(1-Assumptions!D19)^0 -> 7000000 | D5: =Assumptions!E18*'Deploymnet_&_CAPEX_Schedule'!$C$5*(1-Assumptions!E19)^1 -> 6965000 | E5: =Assumptions!F18*'Deploymnet_&_CAPEX_Schedule'!$C$5*(1-Assumptions!F19)^2 -> 6930175 | F5: =Assumptions!G18*'Deploymnet_&_CAPEX_Schedule'!$C$5*(1-Assumptions!G19)^3 -> 6895524.1 | G5: =Assumptions!H18*'Deploymnet_&_CAPEX_Schedule'!$C$5*(1-Assumptions!H19)^4 -> 6861046.5
B6: PPA rate ($/kWh, escalated from COD) | C6: =Assumptions!D20*(1+Assumptions!D21)^0 -> 0.17 | D6: =Assumptions!E20*(1+Assumptions!E21)^1 -> 0.17425 | E6: =Assumptions!F20*(1+Assumptions!F21)^2 -> 0.17860625 | F6: =Assumptions!G20*(1+Assumptions!G21)^3 -> 0.18307141 | G6: =Assumptions!H20*(1+Assumptions!H21)^4 -> 0.18764819
B7: PPA revenue ($) | C7: =C6*C5 -> 1190000 | D7: =D6*D5 -> 1213651.2 | E7: =E6*E5 -> 1237772.6 | F7: =F6*F5 -> 1262373.3 | G7: =G6*G5 -> 1287463
B8: Grid services revenue ($) | C8: =Assumptions!D22*Assumptions!$D$10*(1+Assumptions!D21)^0 -> 500000 | D8: =Assumptions!E22*Assumptions!$D$10*(1+Assumptions!E21)^1 -> 512500 | E8: =Assumptions!F22*Assumptions!$D$10*(1+Assumptions!F21)^2 -> 525312.5 | F8: =Assumptions!G22*Assumptions!$D$10*(1+Assumptions!G21)^3 -> 538445.31 | G8: =Assumptions!H22*Assumptions!$D$10*(1+Assumptions!H21)^4 -> 551906.45
B10: Vintage 2 — Systems Installed Fy2027
B11: Generation (kWh) | C11: 0 | D11: =Assumptions!E18*Assumptions!$E$10*(1-Assumptions!E19)^0 -> 7000000 | E11: =Assumptions!F18*Assumptions!$E$10*(1-Assumptions!F19)^1 -> 6965000 | F11: =Assumptions!G18*Assumptions!$E$10*(1-Assumptions!G19)^2 -> 6930175 | G11: =Assumptions!H18*Assumptions!$E$10*(1-Assumptions!H19)^3 -> 6895524.1
B12: PPA rate ($/kWh, escalated from COD) | C12: 0 | D12: =Assumptions!E20*(1+Assumptions!E21)^0 -> 0.17 | E12: =Assumptions!F20*(1+Assumptions!F21)^1 -> 0.17425 | F12: =Assumptions!G20*(1+Assumptions!G21)^2 -> 0.17860625 | G12: =Assumptions!H20*(1+Assumptions!H21)^3 -> 0.18307141
B13: PPA revenue ($) | C13: 0 | D13: =D12*D11 -> 1190000 | E13: =E12*E11 -> 1213651.2 | F13: =F12*F11 -> 1237772.6 | G13: =G12*G11 -> 1262373.3
B14: Grid services revenue ($) | C14: 0 | D14: =Assumptions!E22*Assumptions!$E$10*(1+Assumptions!E21)^0 -> 500000 | E14: =Assumptions!F22*Assumptions!$E$10*(1+Assumptions!F21)^1 -> 512500 | F14: =Assumptions!G22*Assumptions!$E$10*(1+Assumptions!G21)^2 -> 525312.5 | G14: =Assumptions!H22*Assumptions!$E$10*(1+Assumptions!H21)^3 -> 538445.31
B16: Vintage 3 — Systems Installed Fy2028
B17: Generation (kWh) | C17: 0 | D17: 0 | E17: =Assumptions!F18*Assumptions!$F$10*(1-Assumptions!F19)^0 -> 10500000 | F17: =Assumptions!G18*Assumptions!$F$10*(1-Assumptions!G19)^1 -> 10447500 | G17: =Assumptions!H18*Assumptions!$F$10*(1-Assumptions!H19)^2 -> 10395262
B18: PPA rate ($/kWh, escalated from COD) | C18: 0 | D18: 0 | E18: =Assumptions!F20*(1+Assumptions!F21)^0 -> 0.17 | F18: =Assumptions!G20*(1+Assumptions!G21)^1 -> 0.17425 | G18: =Assumptions!H20*(1+Assumptions!H21)^2 -> 0.17860625
B19: PPA revenue ($) | C19: 0 | D19: 0 | E19: =E17*E18 -> 1785000 | F19: =F17*F18 -> 1820476.9 | G19: =G17*G18 -> 1856658.9
B20: Grid services revenue ($) | C20: 0 | D20: 0 | E20: =Assumptions!F22*Assumptions!$F$10*(1+Assumptions!E21)^0 -> 750000 | F20: =Assumptions!G22*Assumptions!$F$10*(1+Assumptions!F21)^1 -> 768750 | G20: =Assumptions!H22*Assumptions!$F$10*(1+Assumptions!G21)^2 -> 787968.75
B22: Vintage 4 — Systems Installed Fy2029
B23: Generation (kWh) | C23: 0 | D23: 0 | E23: 0 | F23: =Assumptions!G18*Assumptions!$G$10*(1-Assumptions!G19)^0 -> 10500000 | G23: =Assumptions!H18*Assumptions!$G$10*(1-Assumptions!H19)^1 -> 10447500
B24: PPA rate ($/kWh, escalated from COD) | C24: 0 | D24: 0 | E24: 0 | F24: =Assumptions!G20*(1+Assumptions!G21)^0 -> 0.17 | G24: =Assumptions!H20*(1+Assumptions!H21)^1 -> 0.17425
B25: PPA revenue ($) | C25: 0 | D25: 0 | E25: 0 | F25: =F23*F24 -> 1785000 | G25: =G23*G24 -> 1820476.9
B26: Grid services revenue ($) | C26: 0 | D26: 0 | E26: 0 | F26: =Assumptions!G22*Assumptions!$G$10*(1+Assumptions!G21)^0 -> 750000 | G26: =Assumptions!H22*Assumptions!$G$10*(1+Assumptions!H21)^1 -> 768750
B28: Vintage 5 — Systems Installed Fy2030
B29: Generation (kWh) | C29: 0 | D29: 0 | E29: 0 | F29: 0 | G29: =Assumptions!H18*Assumptions!H10*(1-Assumptions!H19)^0 -> 10500000
B30: PPA rate ($/kWh, escalated from COD) | C30: 0 | D30: 0 | E30: 0 | F30: 0 | G30: =Assumptions!H20*(1+Assumptions!H21)^0 -> 0.17
B31: PPA revenue ($) | C31: 0 | D31: 0 | E31: 0 | F31: 0 | G31: =G29*G30 -> 1785000
B32: Grid services revenue ($) | C32: 0 | D32: 0 | E32: 0 | F32: 0 | G32: =Assumptions!H22*Assumptions!H10 -> 750000
B34: Consolidated Project Revenue
B35: Total PPA revenue ($) | C35: =SUM(C7,C13,C19,C25,C31) -> 1190000 | D35: =SUM(D7,D13,D19,D25,D31) -> 2403651.2 | E35: =SUM(E7,E13,E19,E25,E31) -> 4236423.8 | F35: =SUM(F7,F13,F19,F25,F31) -> 6105622.7 | G35: =SUM(G7,G13,G19,G25,G31) -> 8011972
B36: Total grid services revenue ($) | C36: =SUM(C8,C14,C20,C26,C32) -> 500000 | D36: =SUM(D8,D14,D20,D26,D32) -> 1012500 | E36: =SUM(E8,E14,E20,E26,E32) -> 1787812.5 | F36: =SUM(F8,F14,F20,F26,F32) -> 2582507.8 | G36: =SUM(G8,G14,G20,G26,G32) -> 3397070.5
B37: O&M / monitoring cost (% of PPA revenue) | C37: =C35*Assumptions!D23 -> 178500 | D37: =D35*Assumptions!E23 -> 360547.69 | E37: =E35*Assumptions!F23 -> 635463.57 | F37: =F35*Assumptions!G23 -> 915843.41 | G37: =G35*Assumptions!H23 -> 1201795.8
B39: SaaS Licensing (Asset-Light, Company-Wide)
B40: SaaS licensing revenue ($, = cumulative ARR) | C40: =Assumptions!D27 -> 0 | D40: =Assumptions!E27 -> 150000 | E40: =Assumptions!F27 -> 450000 | F40: =Assumptions!G27 -> 1000000 | G40: =Assumptions!H27 -> 1900000
B41: SaaS cost of revenue ($) | C41: =C40*(1-Assumptions!D28) -> 0 | D41: =D40*(1-Assumptions!E28) -> 37500 | E41: =E40*(1-Assumptions!F28) -> 112500 | F41: =F40*(1-Assumptions!G28) -> 250000 | G41: =G40*(1-Assumptions!H28) -> 475000
B43: Total Company Revenue
B44: Total revenue ($) | C44: =SUM(C35,C36,C40) -> 1690000 | D44: =SUM(D35,D36,D40) -> 3566151.2 | E44: =SUM(E35,E36,E40) -> 6474236.3 | F44: =SUM(F35,F36,F40) -> 9688130.6 | G44: =SUM(G35,G36,G40) -> 13309043
B45: PPA revenue mix (%) | C45: =C35/C44 -> 0.70414201 | D45: =D35/D44 -> 0.67401831 | E45: =E35/E44 -> 0.65435113 | F45: =F35/F44 -> 0.63021681 | G45: =G35/G44 -> 0.60199462
B46: YoY revenue growth (%) | C46: n/a | D46: =D44/C44-1 -> 1.1101487 | E46: =E44/D44-1 -> 0.8154688 | F46: =F44/E44-1 -> 0.49641287 | G46: =G44/F44-1 -> 0.37374723

Sheet Cap_Table
B2: Cap Table & Series A Dilution Waterfall
B4: Series A Round Terms
B5: Pre-money valuation ($) | C5: 35000000
B6: New investment ($) | C6: 10000000
B7: Post-money valuation ($) | C7: =SUM(C5:C6) -> 45000000
B8: New investor ownership (%, of post-money) | C8: =C6/C7 -> 0.22222222
B9: Target refreshed option pool (% of post-money, FD) | C9: 0.15
B11: Pre- / Post-Series A Ownership Waterfall
B12: Holder | C12: Instrument | D12: Pre-Series A % | E12: Dilution factor | F12: Post-Series A %
B13: Founders (3) | C13: Common | D13: 0.62 | E13: =(1-$C$8-$C$9)/(SUM(D13,D15,D16)) -> 0.71338384 | F13: =E13*D13 -> 0.44229798
B14: Employee option pool (pre-round) | C14: Options | D14: 0.12 | E14: =$C$9/D14 -> 1.25 | F14: =E14*D14 -> 0.15
B15: Pre-seed / friends & family | C15: SAFE ($750K @ $6M cap, as-converted) | D15: 0.08 | E15: =$E$13 -> 0.71338384 | F15: =E15*D15 -> 0.057070707
B16: Seed investors | C16: Preferred | D16: 0.18 | E16: =$E$13 -> 0.71338384 | F16: =E16*D16 -> 0.12840909
B17: Total pre-Series A | D17: =SUM(D13:D16) -> 1
B19: Series A investors (new) | C19: Preferred | D19: — | F19: =$C$8 -> 0.22222222
B20: Total post-Series A | F20: =SUM(F13:F19) -> 1

Sheet MDM
B2: Years
B3: 46023
B4: 46388
B5: 46753
B6: 47119
B7: 47484
B8: 47849
B9: 48214
B10: 48580
B11: 48945
B12: 49310
